<mujoco model="mantis_v1">
  <compiler angle="radian" meshdir="meshes"/>
  <size njmax="500" nconmax="100" />
  <option gravity="0 0 0"/>

  <asset>
    <mesh name="vehicle" file="vehicle.STL" />
    <mesh name="rear_middle_rudder_link" file="rear_middle_rudder_link.STL" />
    <mesh name="rear_middle_roller_link" file="rear_middle_roller_link.STL" />
    <mesh name="front_right_rudder_link" file="front_right_rudder_link.STL" />
    <mesh name="front_right_roller_link" file="front_right_roller_link.STL" />
    <mesh name="front_left_rudder_link" file="front_left_rudder_link.STL" />
    <mesh name="front_left_roller_link" file="front_left_roller_link.STL" />
    <mesh name="pelvis_link" file="pelvis_link.STL" />
    <mesh name="right_shoulder_pitch_link" file="right_shoulder_pitch_link.STL" />
    <mesh name="right_shoulder_roll_link" file="right_shoulder_roll_link.STL" />
    <mesh name="right_shoulder_yaw_link" file="right_shoulder_yaw_link.STL" />
    <mesh name="right_elbow_link" file="right_elbow_link.STL" />
    <mesh name="right_wrist_roll_link" file="right_wrist_roll_link.STL" />
    <mesh name="right_wrist_pitch_link" file="right_wrist_pitch_link.STL" />
    <mesh name="right_wrist_yaw_link" file="right_wrist_yaw_link.STL" />
    <mesh name="right_clamp_right_link" file="right_clamp_right_link.STL" />
    <mesh name="right_clamp_left_link" file="right_clamp_left_link.STL" />
    <mesh name="left_shoulder_pitch_link" file="left_shoulder_pitch_link.STL" />
    <mesh name="left_shoulder_roll_link" file="left_shoulder_roll_link.STL" />
    <mesh name="left_shoulder_yaw_link" file="left_shoulder_yaw_link.STL" />
    <mesh name="left_elbow_link" file="left_elbow_link.STL" />
    <mesh name="left_wrist_roll_link" file="left_wrist_roll_link.STL" />
    <mesh name="left_wrist_pitch_link" file="left_wrist_pitch_link.STL" />
    <mesh name="left_wrist_yaw_link" file="left_wrist_yaw_link.STL" />
    <mesh name="left_clamp_right_link" file="left_clamp_right_link.STL" />
    <mesh name="left_clamp_left_link" file="left_clamp_left_link.STL" />
    <mesh name="neck_yaw_link" file="neck_yaw_link.STL" />
    <mesh name="neck_pitch_link" file="neck_pitch_link.STL" />
  </asset>

  <worldbody>
    <body name="vehicle" pos="0 0 0" quat="1 0 0 0" mocap="false">
      <!-- <freejoint name="root" /> -->
      <site name="imu_in_vehicle" size="0.01" pos="0 0 0" />
      <geom type="mesh" rgba="1 1 1 1" mesh="vehicle" contype="0" conaffinity="0" density="0" group="1" />
      <geom type="mesh" rgba="1 1 1 1" mesh="vehicle" />
      <body name="rear_middle_rudder_link" pos="-0.3216 0 0.159">
        <inertial pos="0 0 -0.043093" quat="0.707107 0.707107 0 0" mass="0.059006" diaginertia="0.0002195 0.0001381 0.00010325" />
        <joint name="rear_middle_rudder_joint" pos="0 0 0" axis="0 0 1" range="-3.14 3.14" actuatorfrcrange="-100 100" />
        <geom type="mesh" rgba="1 1 1 1" mesh="rear_middle_rudder_link" contype="0" conaffinity="0" density="0" group="1" />
        <geom type="mesh" rgba="1 1 1 1" mesh="rear_middle_rudder_link" />
        <body name="rear_middle_roller_link" pos="0 0 -0.095">
          <inertial pos="-3.7169e-09 3.0991e-06 7.4051e-05" quat="0.5014 0.498596 0.498724 0.501273" mass="0.80865" diaginertia="0.0014046 0.0010514 0.0010489" />
          <joint name="rear_middle_roller_joint" pos="0 0 0" axis="0 -1 0" range="-3.14 3.14" actuatorfrcrange="-100 100" />
          <geom type="mesh" rgba="1 1 1 1" mesh="rear_middle_roller_link" contype="0" conaffinity="0" density="0" group="1" />
          <geom type="mesh" rgba="1 1 1 1" mesh="rear_middle_roller_link" />
        </body>
      </body>
      <body name="front_right_rudder_link" pos="0.1034 -0.17 0.159">
        <inertial pos="0 0 -0.043093" quat="0.707107 0.707107 0 0" mass="0.059006" diaginertia="0.0002195 0.0001381 0.00010325" />
        <joint name="front_right_rudder_joint" pos="0 0 0" axis="0 0 1" range="-3.14 3.14" actuatorfrcrange="-100 100" />
        <geom type="mesh" rgba="1 1 1 1" mesh="front_right_rudder_link" contype="0" conaffinity="0" density="0" group="1" />
        <geom type="mesh" rgba="1 1 1 1" mesh="front_right_rudder_link" />
        <body name="front_right_roller_link" pos="0 0 -0.095">
          <inertial pos="-3.7169e-09 3.0991e-06 7.4051e-05" quat="0.5014 0.498596 0.498724 0.501273" mass="0.80865" diaginertia="0.0014046 0.0010514 0.0010489" />
          <joint name="front_right_roller_joint" pos="0 0 0" axis="0 -1 0" range="-3.14 3.14" actuatorfrcrange="-100 100" />
          <geom type="mesh" rgba="1 1 1 1" mesh="front_right_roller_link" contype="0" conaffinity="0" density="0" group="1" />
          <geom type="mesh" rgba="1 1 1 1" mesh="front_right_roller_link" />
        </body>
      </body>
      <body name="front_left_rudder_link" pos="0.1034 0.17 0.159">
        <inertial pos="0 0 -0.043093" quat="0.707107 0.707107 0 0" mass="0.059006" diaginertia="0.0002195 0.0001381 0.00010325" />
        <joint name="front_left_rudder_joint" pos="0 0 0" axis="0 0 1" range="-3.14 3.14" actuatorfrcrange="-100 100" />
        <geom type="mesh" rgba="1 1 1 1" mesh="front_left_rudder_link" contype="0" conaffinity="0" density="0" group="1" />
        <geom type="mesh" rgba="1 1 1 1" mesh="front_left_rudder_link" />
        <body name="front_left_roller_link" pos="0 0 -0.095">
          <inertial pos="3.7169e-09 -3.0991e-06 7.4051e-05" quat="0.498596 0.5014 0.501273 0.498724" mass="0.80865" diaginertia="0.0014046 0.0010514 0.0010489" />
          <joint name="front_left_roller_joint" pos="0 0 0" axis="0 1 0" range="-3.14 3.14" actuatorfrcrange="-100 100" />
          <geom type="mesh" rgba="1 1 1 1" mesh="front_left_roller_link" contype="0" conaffinity="0" density="0" group="1" />
          <geom type="mesh" rgba="1 1 1 1" mesh="front_left_roller_link" />
        </body>
      </body>
      <body name="pelvis_link" pos="0 0 1.1588">
        <inertial pos="-0.022255 -0.00021026 -0.017073" quat="1 -9.78129e-08 -0.000292309 0.000334621" mass="1.8633" diaginertia="0.0044236 0.0040692 0.0034874" />
        <joint name="pelvis_joint" pos="0 0 0" axis="0 0 1" type="slide" range="-0.49193 0.559" actuatorfrcrange="-100 100" />
        <geom type="mesh" rgba="1 1 1 1" mesh="pelvis_link" contype="0" conaffinity="0" density="0" group="1" />
        <geom type="mesh" rgba="1 1 1 1" mesh="pelvis_link" />
        <body name="right_shoulder_pitch_link" pos="0 -0.11533 0" quat="0.976296 -0.216438 0 0">
          <inertial pos="-0.12282 -0.090349 -5.8329e-09" quat="0.665183 0.665183 -0.239858 -0.239858" mass="0.77765" diaginertia="0.00359543 0.003458 0.00115267" />
          <joint name="right_shoulder_pitch_joint" pos="0 0 0" axis="0 -1 0" range="-3.14 3.14" actuatorfrcrange="-100 100" />
          <geom type="mesh" rgba="1 1 1 1" mesh="right_shoulder_pitch_link" contype="0" conaffinity="0" density="0" group="1" />
          <geom type="mesh" rgba="1 1 1 1" mesh="right_shoulder_pitch_link" />
          <body name="right_shoulder_roll_link" pos="0 -0.115 0" quat="0.976296 0.216438 0 0">
            <inertial pos="-0.018752 6.2931e-05 0.021815" quat="0.00130228 0.63292 -0.0010808 0.774215" mass="0.70801" diaginertia="0.00226896 0.00187581 0.000782498" />
            <joint name="right_shoulder_roll_joint" pos="0 0 0" axis="1 0 0" range="-3.14 3.14" actuatorfrcrange="-100 100" />
            <geom type="mesh" rgba="1 1 1 1" mesh="right_shoulder_roll_link" contype="0" conaffinity="0" density="0" group="1" />
            <geom type="mesh" rgba="1 1 1 1" mesh="right_shoulder_roll_link" />
            <body name="right_shoulder_yaw_link" pos="0 0 0.0045">
              <inertial pos="0.00082898 -0.021155 -0.099194" quat="0.707656 0.00428307 -0.000245105 0.706544" mass="0.89472" diaginertia="0.00243786 0.00175842 0.00104082" />
              <joint name="right_shoulder_yaw_joint" pos="0 0 0" axis="0 0 -1" range="-3.14 3.14" actuatorfrcrange="-100 100" />
              <geom type="mesh" rgba="1 1 1 1" mesh="right_shoulder_yaw_link" contype="0" conaffinity="0" density="0" group="1" />
              <geom type="mesh" rgba="1 1 1 1" mesh="right_shoulder_yaw_link" />
              <body name="right_elbow_link" pos="0 0.002 -0.35548">
                <inertial pos="0.086482 5.5835e-05 -0.00065621" quat="0.696829 0.0587392 0.0577979 0.712488" mass="0.2936" diaginertia="0.000197061 0.000194566 0.000184663" />
                <joint name="right_elbow_joint" pos="0 0 0" axis="0 -1 0" range="-2.477 0.662" actuatorfrcrange="-100 100" />
                <geom type="mesh" rgba="1 1 1 1" mesh="right_elbow_link" contype="0" conaffinity="0" density="0" group="1" />
                <geom type="mesh" rgba="1 1 1 1" mesh="right_elbow_link" />
                <body name="right_wrist_roll_link" pos="0.1275 0 0">
                  <inertial pos="0.03908 2.3234e-07 0.0042743" quat="0.563423 0.427221 0.427259 0.563459" mass="0.18268" diaginertia="0.0001144 0.000108057 8.62682e-05" />
                  <joint name="right_wrist_roll_joint" pos="0 0 0" axis="-1 0 0" range="-3.14 3.14" actuatorfrcrange="-100 100" />
                  <geom type="mesh" rgba="1 1 1 1" mesh="right_wrist_roll_link" contype="0" conaffinity="0" density="0" group="1" />
                  <geom type="mesh" rgba="1 1 1 1" mesh="right_wrist_roll_link" />
                  <body name="right_wrist_pitch_link" pos="0.132 0 0">
                    <inertial pos="0 0.00064955 0" quat="0.706459 0.706459 -0.0302688 0.0302688" mass="0.16063" diaginertia="7.75299e-05 7.69921e-05 6.1244e-05" />
                    <joint name="right_wrist_pitch_joint" pos="0 0 0" axis="0 0 1" range="-2.094 2.094" actuatorfrcrange="-100 100" />
                    <geom type="mesh" rgba="1 1 1 1" mesh="right_wrist_pitch_link" contype="0" conaffinity="0" density="0" group="1" />
                    <geom type="mesh" rgba="1 1 1 1" mesh="right_wrist_pitch_link" />
                    <body name="right_wrist_yaw_link">
                      <inertial pos="0.072416 -3.1956e-05 4.705e-06" quat="0.708026 0.706186 -0.000528209 -0.00102286" mass="0.18746" diaginertia="0.00011976 9.94463e-05 4.97483e-05" />
                      <joint name="right_wrist_yaw_joint" pos="0 0 0" axis="0 1 0" range="-1.744 1.744" actuatorfrcrange="-100 100" />
                      <geom type="mesh" rgba="1 1 1 1" mesh="right_wrist_yaw_link" contype="0" conaffinity="0" density="0" group="1" />
                      <geom type="mesh" rgba="1 1 1 1" mesh="right_wrist_yaw_link" />
                      <body name="right_clamp_right_link" pos="0.1158 -0.0376 0">
                        <inertial pos="0.016969 -0.014264 0.00044012" quat="0.377956 0.354193 0.613429 0.596156" mass="0.0347" diaginertia="1.17339e-05 1.01754e-05 7.0189e-06" />
                        <joint name="right_clamp_right_joint" pos="0 0 0" axis="0 -1 0" type="slide" range="-0.0376 0" actuatorfrcrange="-100 100" />
                        <geom type="mesh" rgba="1 1 1 1" mesh="right_clamp_right_link" contype="0" conaffinity="0" density="0" group="1" />
                        <geom type="mesh" rgba="1 1 1 1" mesh="right_clamp_right_link" />
                      </body>
                      <body name="right_clamp_left_link" pos="0.1158 0.0376 0">
                        <inertial pos="0.016969 0.014264 -0.00044012" quat="0.613429 0.596156 0.377956 0.354193" mass="0.0347" diaginertia="1.17339e-05 1.01754e-05 7.0189e-06" />
                        <joint name="right_clamp_left_joint" pos="0 0 0" axis="0 -1 0" type="slide" range="0 0.0376" actuatorfrcrange="-100 100" />
                        <geom type="mesh" rgba="1 1 1 1" mesh="right_clamp_left_link" contype="0" conaffinity="0" density="0" group="1" />
                        <geom type="mesh" rgba="1 1 1 1" mesh="right_clamp_left_link" />
                      </body>
                    </body>
                  </body>
                </body>
              </body>
            </body>
          </body>
        </body>
        <body name="left_shoulder_pitch_link" pos="0 0.11533 0" quat="0.976296 0.216438 0 0">
          <inertial pos="-0.12282 0.090349 5.7992e-09" quat="0.665183 0.665183 0.239858 0.239858" mass="0.77765" diaginertia="0.00359543 0.003458 0.00115267" />
          <joint name="left_shoulder_pitch_joint" pos="0 0 0" axis="0 1 0" range="-3.14 3.14" actuatorfrcrange="-100 100" />
          <geom type="mesh" rgba="1 1 1 1" mesh="left_shoulder_pitch_link" contype="0" conaffinity="0" density="0" group="1" />
          <geom type="mesh" rgba="1 1 1 1" mesh="left_shoulder_pitch_link" />
          <body name="left_shoulder_roll_link" pos="0 0.115 0" quat="0.976296 -0.216438 0 0">
            <inertial pos="-0.018752 6.2931e-05 0.021815" quat="0.00130228 0.63292 -0.0010808 0.774215" mass="0.70801" diaginertia="0.00226896 0.00187581 0.000782498" />
            <joint name="left_shoulder_roll_joint" pos="0 0 0" axis="1 0 0" range="-3.14 3.14" actuatorfrcrange="-100 100" />
            <geom type="mesh" rgba="1 1 1 1" mesh="left_shoulder_roll_link" contype="0" conaffinity="0" density="0" group="1" />
            <geom type="mesh" rgba="1 1 1 1" mesh="left_shoulder_roll_link" />
            <body name="left_shoulder_yaw_link" pos="0 0 0.0045">
              <inertial pos="0.00070276 0.022035 -0.10012" quat="0.707056 -0.000586006 0.00120977 0.707156" mass="0.87401" diaginertia="0.00237941 0.0017143 0.00101549" />
              <joint name="left_shoulder_yaw_joint" pos="0 0 0" axis="0 0 -1" range="-3.14 3.14" actuatorfrcrange="-100 100" />
              <geom type="mesh" rgba="1 1 1 1" mesh="left_shoulder_yaw_link" contype="0" conaffinity="0" density="0" group="1" />
              <geom type="mesh" rgba="1 1 1 1" mesh="left_shoulder_yaw_link" />
              <body name="left_elbow_link" pos="0 -0.002 -0.35548">
                <inertial pos="0.086482 5.5835e-05 -0.00065621" quat="0.696829 0.0587392 0.0577979 0.712488" mass="0.2936" diaginertia="0.000197061 0.000194566 0.000184663" />
                <joint name="left_elbow_joint" pos="0 0 0" axis="0 -1 0" range="-2.477 0.662" actuatorfrcrange="-100 100" />
                <geom type="mesh" rgba="1 1 1 1" mesh="left_elbow_link" contype="0" conaffinity="0" density="0" group="1" />
                <geom type="mesh" rgba="1 1 1 1" mesh="left_elbow_link" />
                <body name="left_wrist_roll_link" pos="0.1275 0 0">
                  <inertial pos="0.03908 2.3234e-07 0.0042743" quat="0.563423 0.427221 0.427259 0.563459" mass="0.18268" diaginertia="0.0001144 0.000108057 8.62682e-05" />
                  <joint name="left_wrist_roll_joint" pos="0 0 0" axis="-1 0 0" range="-3.14 3.14" actuatorfrcrange="-100 100" />
                  <geom type="mesh" rgba="1 1 1 1" mesh="left_wrist_roll_link" contype="0" conaffinity="0" density="0" group="1" />
                  <geom type="mesh" rgba="1 1 1 1" mesh="left_wrist_roll_link" />
                  <body name="left_wrist_pitch_link" pos="0.132 0 0">
                    <inertial pos="0 -0.00064955 0" quat="0.706459 0.706459 0.0302688 -0.0302688" mass="0.16063" diaginertia="7.75299e-05 7.69921e-05 6.1244e-05" />
                    <joint name="left_wrist_pitch_joint" pos="0 0 0" axis="0 0 1" range="-2.094 2.094" actuatorfrcrange="-100 100" />
                    <geom type="mesh" rgba="1 1 1 1" mesh="left_wrist_pitch_link" contype="0" conaffinity="0" density="0" group="1" />
                    <geom type="mesh" rgba="1 1 1 1" mesh="left_wrist_pitch_link" />
                    <body name="left_wrist_yaw_link">
                      <inertial pos="0.072416 3.1956e-05 -4.705e-06" quat="0.708026 0.706186 0.000528209 0.00102286" mass="0.18746" diaginertia="0.00011976 9.94463e-05 4.97483e-05" />
                      <joint name="left_wrist_yaw_joint" pos="0 0 0" axis="0 1 0" range="-1.744 1.744" actuatorfrcrange="-100 100" />
                      <geom type="mesh" rgba="1 1 1 1" mesh="left_wrist_yaw_link" contype="0" conaffinity="0" density="0" group="1" />
                      <geom type="mesh" rgba="1 1 1 1" mesh="left_wrist_yaw_link" />
                      <body name="left_clamp_right_link" pos="0.1158 -0.0376 0">
                        <inertial pos="0.016969 -0.014264 0.00044012" quat="0.377956 0.354193 0.613429 0.596156" mass="0.0347" diaginertia="1.17339e-05 1.01754e-05 7.0189e-06" />
                        <joint name="left_clamp_right_joint" pos="0 0 0" axis="0 1 0" type="slide" range="0 0.0376" actuatorfrcrange="-100 100" />
                        <geom type="mesh" rgba="1 1 1 1" mesh="left_clamp_right_link" contype="0" conaffinity="0" density="0" group="1" />
                        <geom type="mesh" rgba="1 1 1 1" mesh="left_clamp_right_link" />
                      </body>
                      <body name="left_clamp_left_link" pos="0.1158 0.0376 0">
                        <inertial pos="0.016969 0.014264 -0.00044012" quat="0.613429 0.596156 0.377956 0.354193" mass="0.0347" diaginertia="1.17339e-05 1.01754e-05 7.0189e-06" />
                        <joint name="left_clamp_left_joint" pos="0 0 0" axis="0 1 0" type="slide" range="-0.0376 0" actuatorfrcrange="-100 100" />
                        <geom type="mesh" rgba="1 1 1 1" mesh="left_clamp_left_link" contype="0" conaffinity="0" density="0" group="1" />
                        <geom type="mesh" rgba="1 1 1 1" mesh="left_clamp_left_link" />
                      </body>
                    </body>
                  </body>
                </body>
              </body>
            </body>
          </body>
        </body>
        <body name="neck_yaw_link" pos="-0.0155 0 0.020194">
          <inertial pos="-7.7659e-06 0.00036629 0.040933" quat="0.488205 0.511527 -0.511648 0.48807" mass="0.059102" diaginertia="3.68061e-05 2.8865e-05 2.30939e-05" />
          <joint name="neck_yaw_joint" pos="0 0 0" axis="0 0 1" range="-1.744 1.744" actuatorfrcrange="-100 100" />
          <geom type="mesh" rgba="1 1 1 1" mesh="neck_yaw_link" contype="0" conaffinity="0" density="0" group="1" />
          <geom type="mesh" rgba="1 1 1 1" mesh="neck_yaw_link" />
          <body name="neck_pitch_link" pos="0 0 0.085056">
            <inertial pos="0.014656 -0.00011074 0.074281" quat="0.703997 -0.0112488 -0.0307615 0.709447" mass="0.46933" diaginertia="0.00201196 0.00167772 0.00118162" />
            <joint name="neck_pitch_joint" pos="0 0 0" axis="0 1 0" range="-1.3 1.256" actuatorfrcrange="-100 100" />
            <geom type="mesh" rgba="1 1 1 1" mesh="neck_pitch_link" contype="0" conaffinity="0" density="0" group="1" />
            <geom type="mesh" rgba="1 1 1 1" mesh="neck_pitch_link" />
          </body>
        </body>
      </body>
    </body>
  </worldbody>

  <actuator>
    <motor name="rear_middle_rudder_joint" joint="rear_middle_rudder_joint" />
    <motor name="rear_middle_roller_joint" joint="rear_middle_roller_joint" />
    <motor name="front_right_rudder_joint" joint="front_right_rudder_joint" />
    <motor name="front_right_roller_joint" joint="front_right_roller_joint" />
    <motor name="front_left_rudder_joint" joint="front_left_rudder_joint" />
    <motor name="front_left_roller_joint" joint="front_left_roller_joint" />
    <motor name="pelvis_joint" joint="pelvis_joint" />
    <motor name="right_shoulder_pitch_joint" joint="right_shoulder_pitch_joint" />
    <motor name="right_shoulder_roll_joint" joint="right_shoulder_roll_joint" />
    <motor name="right_shoulder_yaw_joint" joint="right_shoulder_yaw_joint" />
    <motor name="right_elbow_joint" joint="right_elbow_joint" />
    <motor name="right_wrist_roll_joint" joint="right_wrist_roll_joint" />
    <motor name="right_wrist_pitch_joint" joint="right_wrist_pitch_joint" />
    <motor name="right_wrist_yaw_joint" joint="right_wrist_yaw_joint" />
    <motor name="right_clamp_right_joint" joint="right_clamp_right_joint" />
    <motor name="right_clamp_left_joint" joint="right_clamp_left_joint" />
    <motor name="left_shoulder_pitch_joint" joint="left_shoulder_pitch_joint" />
    <motor name="left_shoulder_roll_joint" joint="left_shoulder_roll_joint" />
    <motor name="left_shoulder_yaw_joint" joint="left_shoulder_yaw_joint" />
    <motor name="left_elbow_joint" joint="left_elbow_joint" />
    <motor name="left_wrist_roll_joint" joint="left_wrist_roll_joint" />
    <motor name="left_wrist_pitch_joint" joint="left_wrist_pitch_joint" />
    <motor name="left_wrist_yaw_joint" joint="left_wrist_yaw_joint" />
    <motor name="left_clamp_right_joint" joint="left_clamp_right_joint" />
    <motor name="left_clamp_left_joint" joint="left_clamp_left_joint" />
    <motor name="neck_yaw_joint" joint="neck_yaw_joint" />
    <motor name="neck_pitch_joint" joint="neck_pitch_joint" />
  </actuator>

  <sensor>
    <gyro name="imu-vehicle-angular-velocity" site="imu_in_vehicle" noise="5e-4" cutoff="34.9"/>
    <accelerometer name="imu-vehicle-linear-acceleration" site="imu_in_vehicle" noise="1e-2" cutoff="157"/>
  </sensor>
  
  <!-- setup scene -->
  <statistic center="1.0 0.7 1.0" extent="0.8"/>

  <visual>
    <headlight diffuse="0.6 0.6 0.6" ambient="0.1 0.1 0.1" specular="0.9 0.9 0.9"/>
    <rgba haze="0.15 0.25 0.35 1"/>
    <global azimuth="-140" elevation="-20"/>
  </visual>

  <asset>
    <texture type="skybox" builtin="gradient" rgb1="0.3 0.5 0.7" rgb2="0 0 0" width="512" height="3072"/>
    <texture type="2d" name="groundplane" builtin="checker" mark="edge" rgb1="0.2 0.3 0.4" rgb2="0.1 0.2 0.3"
        markrgb="0.8 0.8 0.8" width="300" height="300"/>
    <material name="groundplane" texture="groundplane" texuniform="true" texrepeat="5 5" reflectance="0.2"/>
  </asset>

  <worldbody>
    <light pos="1 0 3.5" dir="0 0 -1" directional="true"/>
    <geom name="floor" size="0 0 0.05" type="plane" material="groundplane"/>
  </worldbody>

</mujoco>